Traceback (most recent call last):
  File "C:\Users\Gregor Debus\AppData\Local\Programs\Python\Python311\Lib\site-packages\jupyter_cache\executors\utils.py", line 58, in single_nb_execution
    executenb(
  File "C:\Users\Gregor Debus\AppData\Local\Programs\Python\Python311\Lib\site-packages\nbclient\client.py", line 1305, in execute
    return NotebookClient(nb=nb, resources=resources, km=km, **kwargs).execute()
           ^^^^^^^^^^^^^^^^^^^^^^^^^^^^^^^^^^^^^^^^^^^^^^^^^^^^^^^^^^^^^^^^^^^^^
  File "C:\Users\Gregor Debus\AppData\Local\Programs\Python\Python311\Lib\site-packages\jupyter_core\utils\__init__.py", line 168, in wrapped
    return loop.run_until_complete(inner)
           ^^^^^^^^^^^^^^^^^^^^^^^^^^^^^^
  File "C:\Users\Gregor Debus\AppData\Local\Programs\Python\Python311\Lib\asyncio\base_events.py", line 653, in run_until_complete
    return future.result()
           ^^^^^^^^^^^^^^^
  File "C:\Users\Gregor Debus\AppData\Local\Programs\Python\Python311\Lib\site-packages\nbclient\client.py", line 705, in async_execute
    await self.async_execute_cell(
  File "C:\Users\Gregor Debus\AppData\Local\Programs\Python\Python311\Lib\site-packages\nbclient\client.py", line 1058, in async_execute_cell
    await self._check_raise_for_error(cell, cell_index, exec_reply)
  File "C:\Users\Gregor Debus\AppData\Local\Programs\Python\Python311\Lib\site-packages\nbclient\client.py", line 914, in _check_raise_for_error
    raise CellExecutionError.from_cell_and_msg(cell, exec_reply_content)
nbclient.exceptions.CellExecutionError: An error occurred while executing the following cell:
------------------
from scipy import stats
import pandas as pd
df2 = pd.read_csv("files_for_python_code\df_sexist_jokes.csv")

column_pairs = [
    ('Low SSC Char. Enjoym.', 'High SSC Char. Enjoym.'),
    ('Low SSC Char. Appr.', 'High SSC Char. Appr.'),
    ('Low SSC Def. Enjoym.', 'High SSC Def. Enjoym.'),
    ('Low SSC Def. Appr.', 'High SSC Def. Appr.')
]

for col1, col2 in column_pairs:
    t_stat, p_value = stats.ttest_ind(df2[col1].dropna(), df2[col2].dropna())
    print(f'The p-value for {col1} and {col2} is {p_value:.30f}')
------------------


[1;31m---------------------------------------------------------------------------[0m
[1;31mModuleNotFoundError[0m                       Traceback (most recent call last)
Cell [1;32mIn[1], line 1[0m
[1;32m----> 1[0m [38;5;28;01mfrom[39;00m [38;5;21;01mscipy[39;00m [38;5;28;01mimport[39;00m stats
[0;32m      2[0m [38;5;28;01mimport[39;00m [38;5;21;01mpandas[39;00m [38;5;28;01mas[39;00m [38;5;21;01mpd[39;00m
[0;32m      3[0m df2 [38;5;241m=[39m pd[38;5;241m.[39mread_csv([38;5;124m"[39m[38;5;124mfiles_for_python_code[39m[38;5;124m\[39m[38;5;124mdf_sexist_jokes.csv[39m[38;5;124m"[39m)

[1;31mModuleNotFoundError[0m: No module named 'scipy'

